<mujoco model="alpha_single">

  <compiler angle="radian" autolimits="true"/>
  <option timestep="0.005"
          solver="Newton"
          iterations="50"/>
  <default>
    <geom solref="0.05 1" solimp="0.9 0.95 0.001"/>
    <joint damping="0.25" armature="0.01"/>
  </default>

  <asset>
    <texture type="2d" name="groundplane" builtin="checker"
             rgb1="0.2 0.3 0.4" rgb2="0.1 0.2 0.3"
             markrgb="0.8 0.8 0.8" width="300" height="300"/>
    <material name="groundplane" texture="groundplane" texuniform="true"
              texrepeat="5 5" reflectance="0.2"/>
  </asset>

  <worldbody>
    <light pos="0 0 3" dir="0 0 -1" diffuse="0.8 0.8 0.8"/>
    <geom name="floor" size="100 100 0.1" type="plane" material="groundplane"
          condim="3" friction="1 0.1 0.01"/>

    <body name="root" pos="0 0 0.298" quat="1 0 0 0">
      <freejoint name="freejoint"/>
      <geom name="Body_link_col0" type="box" size="0.045 0.0525 0.0535"
            pos="0 0 0" rgba="0.2 0.6 0.9 1" condim="3"/>
      <inertial pos="0 0 0" mass="0.42"
                diaginertia="0.00078659 0.000684215 0.000669375"/>

      <body name="Head_link" pos="0 0 0.0855" quat="1 0 0 0">
        <geom name="Head_link_col0" type="sphere" size="0.045" pos="0 0 0" condim="3"/>
        <inertial pos="0 0 0" mass="0.066"
                  diaginertia="3.7125e-05 3.7125e-05 3.7125e-05"/>
      </body>

      <!-- Left leg -->
      <body name="Left_Lateral_Thigh_link" pos="0.0025 0.03 -0.0535"
            quat="0.707105 0 0.707108 0">
        <joint name="Left_Lateral_Thigh_link_joint" type="hinge" axis="0 0 1"
               range="-1.0 1.93" frictionloss="0.15"/>
        <geom name="Left_Lateral_Thigh_link_col0" type="box" size="0.02 0.02 0.0225"
              pos="0.0225 0 0" quat="0.707105 0 -0.707108 0" condim="3"/>
        <inertial pos="0 0 0" mass="0.07"
                  diaginertia="2.114583e-05 2.114583e-05 1.8667e-05"/>
        <body name="Left_Thigt_link" pos="0.0445 0 0"
              quat="0.499998 0.500000 -0.500000 0.500002">
          <joint name="Left_Thigt_link_joint" type="hinge" axis="0 0 1"
                 range="-1.57 1.57" frictionloss="0.15"/>
          <geom name="Left_Thigt_link_col0" type="box" size="0.0175 0.02 0.025"
                pos="0 -0.025 0" quat="0.707105 -0.707108 0 0" condim="3"/>
          <inertial pos="0 0 0" mass="0.115"
                    diaginertia="3.929166e-05 3.569791e-05 2.7073e-05"/>
          <body name="Left_Leg_Link" pos="-0.025 -0.050 0" quat="1 0 0 0">
            <joint name="Left_Leg_Link_joint" type="hinge" axis="0 0 1"
                   range="-2.7 0.3" frictionloss="0.15"/>
            <geom name="Left_Leg_Link_col0" type="box" size="0.0175 0.025 0.03"
                  pos="0 -0.03 0" quat="0.707105 -0.707108 0 0" condim="3"/>
            <inertial pos="0 0 0" mass="0.11"
                      diaginertia="5.5917e-05 4.4229e-05 3.4146e-05"/>
            <body name="Left_Ankle_link" pos="0 -0.06 0" quat="1 0 0 0">
              <joint name="Left_Ankle_link_joint" type="hinge" axis="0 0 1"
                     range="-1.57 1.57" frictionloss="0.15"/>
              <geom name="Left_Ankle_link_col0" type="box" size="0.0175 0.02 0.021"
                    pos="0 -0.021 0" quat="0.707105 -0.707108 0 0" condim="3"/>
              <inertial pos="0 0 0" mass="0.055"
                        diaginertia="1.5418e-05 1.37e-05 1.2948e-05"/>
              <body name="Left_Feet_link" pos="0 -0.047 0"
                    quat="0.499998 -0.500000 0.500002 -0.500000">
                <joint name="Left_Feet_link_joint" type="hinge" axis="0 0 1"
                       range="-1.57 0.43" frictionloss="0.15"/>
                <geom name="Left_Feet_link_col0" type="box" size="0.055 0.04 0.014"
                      pos="0.009 0.016 0" quat="-0.707108 0.000002 0.707105 0.000002"
                      condim="3"/>
                <inertial pos="0 0 0" mass="0.07"
                          diaginertia="4.1907e-05 7.5157e-05 0.000107917"/>
              </body>
            </body>
          </body>
        </body>
      </body>

      <!-- Left arm -->
      <body name="Left_Shoulder_link" pos="0.012 0.0525 0.0335"
            quat="0.707105 0.707108 0 0">
        <joint name="Left_Shoulder_link_joint" type="hinge" axis="0 0 1"
               range="0.0 3.1416" frictionloss="0.15"/>
        <geom name="Left_Shoulder_link_col0" type="box" size="0.02 0.01 0.02"
              pos="0 0 -0.01" quat="0.707105 -0.707108 0 0" condim="3"/>
        <inertial pos="0 0 0" mass="0.06" diaginertia="1e-05 1.6e-05 1e-05"/>
        <body name="Left_Arm_link" pos="0 0 -0.02"
              quat="0.499998 -0.500000 0.500002 -0.500000">
          <joint name="Left_Arm_link_joint" type="hinge" axis="0 0 1"
                 range="-1.57 1.57" frictionloss="0.15"/>
          <geom name="Left_Arm_link_col0" type="box" size="0.02 0.03 0.0175"
                pos="0 0.03 0" quat="0.707105 0 -0.707108 0" condim="3"/>
          <inertial pos="0 0 0" mass="0.0475"
                    diaginertia="1.9099e-05 1.1182e-05 2.0583e-05"/>
          <body name="Left_Hand_link" pos="0 0.06 0" quat="1 0 0 0">
            <joint name="Left_Hand_link_joint" type="hinge" axis="0 0 1"
                   range="-1.57 1.57" frictionloss="0.15"/>
            <geom name="Left_Hand_link_col0" type="box" size="0.02 0.0425 0.0175"
                  pos="0 0.0425 0" quat="0.707105 0 -0.707108 0" condim="3"/>
            <inertial pos="0 0 0" mass="0.02"
                      diaginertia="1.4083e-05 4.708e-06 1.4708e-05"/>
          </body>
        </body>
      </body>

      <!-- Right leg -->
      <body name="Right_Lateral_Thigh_link" pos="0.0025 -0.03 -0.0535"
            quat="0.707105 0 0.707108 0">
        <joint name="Right_Lateral_Thigh_link_joint" type="hinge" axis="0 0 1"
               range="-1.93 1.0" frictionloss="0.15"/>
        <geom name="Right_Lateral_Thigh_link_col0" type="box" size="0.02 0.02 0.0225"
              pos="0.0225 0 0" quat="0.707105 0 -0.707108 0" condim="3"/>
        <inertial pos="0 0 0" mass="0.07"
                  diaginertia="2.114583e-05 2.114583e-05 1.8667e-05"/>
        <body name="Right_Thigh_link" pos="0.0445 0 0"
              quat="0.499998 0.500000 -0.500000 0.500002">
          <joint name="Right_Thigh_link_joint" type="hinge" axis="0 0 1"
                 range="-1.57 1.57" frictionloss="0.15"/>
          <geom name="Right_Thigh_link_col0" type="box" size="0.0175 0.02 0.025"
                pos="0 -0.025 0" quat="0.707105 -0.707108 0 0" condim="3"/>
          <inertial pos="0 0 0" mass="0.115"
                    diaginertia="3.929166e-05 3.569791e-05 2.7073e-05"/>
          <body name="Right_Leg_link" pos="-0.025 -0.050 0" quat="1 0 0 0">
            <joint name="Right_Leg_link_joint" type="hinge" axis="0 0 1"
                   range="-2.7 0.3" frictionloss="0.15"/>
            <geom name="Right_Leg_link_col0" type="box" size="0.0175 0.025 0.03"
                  pos="0 -0.03 0" quat="0.707105 -0.707108 0 0" condim="3"/>
            <inertial pos="0 0 0" mass="0.11"
                      diaginertia="5.5917e-05 4.4229e-05 3.4146e-05"/>
            <body name="Right_Ankle_link" pos="0 -0.06 0" quat="1 0 0 0">
              <joint name="Right_Ankle_link_joint" type="hinge" axis="0 0 1"
                     range="-1.57 1.57" frictionloss="0.15"/>
              <geom name="Right_Ankle_link_col0" type="box" size="0.0175 0.02 0.021"
                    pos="0 -0.021 0" quat="0.707105 -0.707108 0 0" condim="3"/>
              <inertial pos="0 0 0" mass="0.055"
                        diaginertia="1.5418e-05 1.37e-05 1.2948e-05"/>
              <body name="Right_Feet_link" pos="0 -0.047 0"
                    quat="0.499998 -0.500000 0.500002 -0.500000">
                <joint name="Right_Feet_link_joint" type="hinge" axis="0 0 1"
                       range="-0.43 1.57" frictionloss="0.15"/>
                <geom name="Right_Feet_link_col0" type="box" size="0.055 0.04 0.014"
                      pos="0.009 -0.016 0" quat="-0.707108 0.000002 0.707105 0.000002"
                      condim="3"/>
                <inertial pos="0 0 0" mass="0.07"
                          diaginertia="4.1907e-05 7.5157e-05 0.000107917"/>
              </body>
            </body>
          </body>
        </body>
      </body>

      <!-- Right arm -->
      <body name="Right_Shoulder_link" pos="0.012 -0.0525 0.0335"
            quat="0.707105 0.707108 0 0">
        <joint name="Right_Shoulder_link_joint" type="hinge" axis="0 0 1"
               range="0.0 3.1416" frictionloss="0.15"/>
        <geom name="Right_Shoulder_link_col0" type="box" size="0.02 0.01 0.02"
              pos="0 0 0.01" quat="0.707105 -0.707108 0 0" condim="3"/>
        <inertial pos="0 0 0" mass="0.06" diaginertia="1e-05 1.6e-05 1e-05"/>
        <body name="Right_Arm_link" pos="0 0 0.02"
              quat="0.499998 -0.500000 0.500002 -0.500000">
          <joint name="Right_Arm_link_joint" type="hinge" axis="0 0 1"
                 range="-1.57 1.57" frictionloss="0.15"/>
          <geom name="Right_Arm_link_col0" type="box" size="0.02 0.03 0.0175"
                pos="0 -0.03 0" quat="0.707105 0 -0.707108 0" condim="3"/>
          <inertial pos="0 0 0" mass="0.0475"
                    diaginertia="1.9099e-05 1.1182e-05 2.0583e-05"/>
          <body name="Right_Hand_link" pos="0 -0.06 0" quat="1 0 0 0">
            <joint name="Right_Hand_link_joint" type="hinge" axis="0 0 1"
                   range="-1.57 1.57" frictionloss="0.15"/>
            <geom name="Right_Hand_link_col0" type="box" size="0.02 0.0425 0.0175"
                  pos="0 -0.0425 0" quat="0.707105 0 -0.707108 0" condim="3"/>
            <inertial pos="0 0 0" mass="0.02"
                      diaginertia="1.4083e-05 4.708e-06 1.4708e-05"/>
          </body>
        </body>
      </body>

    </body>
  </worldbody>

  <actuator>
    <!-- Left leg (5 joints) -->
    <position name="act_Left_Lateral_Thigh" joint="Left_Lateral_Thigh_link_joint"
              kp="20" kv="10" ctrlrange="-1.0 1.93"   forcerange="-1.5 1.5"/>
    <position name="act_Left_Thigt"         joint="Left_Thigt_link_joint"
              kp="20" kv="10" ctrlrange="-1.57 1.57"  forcerange="-1.5 1.5"/>
    <position name="act_Left_Leg"           joint="Left_Leg_Link_joint"
              kp="20" kv="10" ctrlrange="-2.7 0.3"    forcerange="-1.5 1.5"/>
    <position name="act_Left_Ankle"         joint="Left_Ankle_link_joint"
              kp="20" kv="10" ctrlrange="-1.57 1.57"  forcerange="-1.5 1.5"/>
    <position name="act_Left_Feet"          joint="Left_Feet_link_joint"
              kp="20" kv="10" ctrlrange="-1.57 0.43"  forcerange="-1.5 1.5"/>
    <!-- Left arm (3 joints) -->
    <position name="act_Left_Shoulder"      joint="Left_Shoulder_link_joint"
              kp="20" kv="10" ctrlrange="0.0 3.1416"  forcerange="-1.5 1.5"/>
    <position name="act_Left_Arm"           joint="Left_Arm_link_joint"
              kp="20" kv="10" ctrlrange="-1.57 1.57"  forcerange="-1.5 1.5"/>
    <position name="act_Left_Hand"          joint="Left_Hand_link_joint"
              kp="20" kv="10" ctrlrange="-1.57 1.57"  forcerange="-1.5 1.5"/>
    <!-- Right leg (5 joints) -->
    <position name="act_Right_Lateral_Thigh" joint="Right_Lateral_Thigh_link_joint"
              kp="20" kv="10" ctrlrange="-1.93 1.0"   forcerange="-1.5 1.5"/>
    <position name="act_Right_Thigh"         joint="Right_Thigh_link_joint"
              kp="20" kv="10" ctrlrange="-1.57 1.57"  forcerange="-1.5 1.5"/>
    <position name="act_Right_Leg"           joint="Right_Leg_link_joint"
              kp="20" kv="10" ctrlrange="-2.7 0.3"    forcerange="-1.5 1.5"/>
    <position name="act_Right_Ankle"         joint="Right_Ankle_link_joint"
              kp="20" kv="10" ctrlrange="-1.57 1.57"  forcerange="-1.5 1.5"/>
    <position name="act_Right_Feet"          joint="Right_Feet_link_joint"
              kp="20" kv="10" ctrlrange="-0.43 1.57"  forcerange="-1.5 1.5"/>
    <!-- Right arm (3 joints) -->
    <position name="act_Right_Shoulder"      joint="Right_Shoulder_link_joint"
              kp="20" kv="10" ctrlrange="0.0 3.1416"  forcerange="-1.5 1.5"/>
    <position name="act_Right_Arm"           joint="Right_Arm_link_joint"
              kp="20" kv="10" ctrlrange="-1.57 1.57"  forcerange="-1.5 1.5"/>
    <position name="act_Right_Hand"          joint="Right_Hand_link_joint"
              kp="20" kv="10" ctrlrange="-1.57 1.57"  forcerange="-1.5 1.5"/>
  </actuator>

</mujoco>
