<mujoco model="alpha1_fight">

  <compiler angle="radian" autolimits="true"/>
  <option timestep="0.005"
          solver="Newton"
          iterations="50"/>
  <default>
    <geom solref="0.05 1" solimp="0.9 0.95 0.001"/>
    <joint damping="0.25" armature="0.01"/>
  </default>

  <asset>
    <texture type="2d" name="groundplane" builtin="checker"
             rgb1="0.2 0.3 0.4" rgb2="0.1 0.2 0.3"
             markrgb="0.8 0.8 0.8" width="300" height="300"/>
    <material name="groundplane" texture="groundplane" texuniform="true"
              texrepeat="5 5" reflectance="0.2"/>
  </asset>

  <contact>
    <!-- Exclude all same-chain (ancestor-descendant) body pairs within each robot.
         The real robot's joint limits prevent same-chain overlaps in practice.
         Cross-chain siblings (left leg ↔ right leg, arm ↔ opposite leg) remain active.
         All cross-robot contacts remain active. -->
    <exclude body1="red_root" body2="red_Head_link"/>
    <exclude body1="red_root" body2="red_Left_Lateral_Thigh_link"/>
    <exclude body1="red_root" body2="red_Left_Thigt_link"/>
    <exclude body1="red_Left_Lateral_Thigh_link" body2="red_Left_Thigt_link"/>
    <exclude body1="red_root" body2="red_Left_Leg_Link"/>
    <exclude body1="red_Left_Lateral_Thigh_link" body2="red_Left_Leg_Link"/>
    <exclude body1="red_Left_Thigt_link" body2="red_Left_Leg_Link"/>
    <exclude body1="red_root" body2="red_Left_Ankle_link"/>
    <exclude body1="red_Left_Lateral_Thigh_link" body2="red_Left_Ankle_link"/>
    <exclude body1="red_Left_Thigt_link" body2="red_Left_Ankle_link"/>
    <exclude body1="red_Left_Leg_Link" body2="red_Left_Ankle_link"/>
    <exclude body1="red_root" body2="red_Left_Feet_link"/>
    <exclude body1="red_Left_Lateral_Thigh_link" body2="red_Left_Feet_link"/>
    <exclude body1="red_Left_Thigt_link" body2="red_Left_Feet_link"/>
    <exclude body1="red_Left_Leg_Link" body2="red_Left_Feet_link"/>
    <exclude body1="red_Left_Ankle_link" body2="red_Left_Feet_link"/>
    <exclude body1="red_root" body2="red_Left_Shoulder_link"/>
    <exclude body1="red_root" body2="red_Left_Arm_link"/>
    <exclude body1="red_Left_Shoulder_link" body2="red_Left_Arm_link"/>
    <exclude body1="red_root" body2="red_Left_Hand_link"/>
    <exclude body1="red_Left_Shoulder_link" body2="red_Left_Hand_link"/>
    <exclude body1="red_Left_Arm_link" body2="red_Left_Hand_link"/>
    <exclude body1="red_root" body2="red_Right_Lateral_Thigh_link"/>
    <exclude body1="red_root" body2="red_Right_Thigh_link"/>
    <exclude body1="red_Right_Lateral_Thigh_link" body2="red_Right_Thigh_link"/>
    <exclude body1="red_root" body2="red_Right_Leg_link"/>
    <exclude body1="red_Right_Lateral_Thigh_link" body2="red_Right_Leg_link"/>
    <exclude body1="red_Right_Thigh_link" body2="red_Right_Leg_link"/>
    <exclude body1="red_root" body2="red_Right_Ankle_link"/>
    <exclude body1="red_Right_Lateral_Thigh_link" body2="red_Right_Ankle_link"/>
    <exclude body1="red_Right_Thigh_link" body2="red_Right_Ankle_link"/>
    <exclude body1="red_Right_Leg_link" body2="red_Right_Ankle_link"/>
    <exclude body1="red_root" body2="red_Right_Feet_link"/>
    <exclude body1="red_Right_Lateral_Thigh_link" body2="red_Right_Feet_link"/>
    <exclude body1="red_Right_Thigh_link" body2="red_Right_Feet_link"/>
    <exclude body1="red_Right_Leg_link" body2="red_Right_Feet_link"/>
    <exclude body1="red_Right_Ankle_link" body2="red_Right_Feet_link"/>
    <exclude body1="red_root" body2="red_Right_Shoulder_link"/>
    <exclude body1="red_root" body2="red_Right_Arm_link"/>
    <exclude body1="red_Right_Shoulder_link" body2="red_Right_Arm_link"/>
    <exclude body1="red_root" body2="red_Right_Hand_link"/>
    <exclude body1="red_Right_Shoulder_link" body2="red_Right_Hand_link"/>
    <exclude body1="red_Right_Arm_link" body2="red_Right_Hand_link"/>
    <exclude body1="blue_root" body2="blue_Head_link"/>
    <exclude body1="blue_root" body2="blue_Left_Lateral_Thigh_link"/>
    <exclude body1="blue_root" body2="blue_Left_Thigt_link"/>
    <exclude body1="blue_Left_Lateral_Thigh_link" body2="blue_Left_Thigt_link"/>
    <exclude body1="blue_root" body2="blue_Left_Leg_Link"/>
    <exclude body1="blue_Left_Lateral_Thigh_link" body2="blue_Left_Leg_Link"/>
    <exclude body1="blue_Left_Thigt_link" body2="blue_Left_Leg_Link"/>
    <exclude body1="blue_root" body2="blue_Left_Ankle_link"/>
    <exclude body1="blue_Left_Lateral_Thigh_link" body2="blue_Left_Ankle_link"/>
    <exclude body1="blue_Left_Thigt_link" body2="blue_Left_Ankle_link"/>
    <exclude body1="blue_Left_Leg_Link" body2="blue_Left_Ankle_link"/>
    <exclude body1="blue_root" body2="blue_Left_Feet_link"/>
    <exclude body1="blue_Left_Lateral_Thigh_link" body2="blue_Left_Feet_link"/>
    <exclude body1="blue_Left_Thigt_link" body2="blue_Left_Feet_link"/>
    <exclude body1="blue_Left_Leg_Link" body2="blue_Left_Feet_link"/>
    <exclude body1="blue_Left_Ankle_link" body2="blue_Left_Feet_link"/>
    <exclude body1="blue_root" body2="blue_Left_Shoulder_link"/>
    <exclude body1="blue_root" body2="blue_Left_Arm_link"/>
    <exclude body1="blue_Left_Shoulder_link" body2="blue_Left_Arm_link"/>
    <exclude body1="blue_root" body2="blue_Left_Hand_link"/>
    <exclude body1="blue_Left_Shoulder_link" body2="blue_Left_Hand_link"/>
    <exclude body1="blue_Left_Arm_link" body2="blue_Left_Hand_link"/>
    <exclude body1="blue_root" body2="blue_Right_Lateral_Thigh_link"/>
    <exclude body1="blue_root" body2="blue_Right_Thigh_link"/>
    <exclude body1="blue_Right_Lateral_Thigh_link" body2="blue_Right_Thigh_link"/>
    <exclude body1="blue_root" body2="blue_Right_Leg_link"/>
    <exclude body1="blue_Right_Lateral_Thigh_link" body2="blue_Right_Leg_link"/>
    <exclude body1="blue_Right_Thigh_link" body2="blue_Right_Leg_link"/>
    <exclude body1="blue_root" body2="blue_Right_Ankle_link"/>
    <exclude body1="blue_Right_Lateral_Thigh_link" body2="blue_Right_Ankle_link"/>
    <exclude body1="blue_Right_Thigh_link" body2="blue_Right_Ankle_link"/>
    <exclude body1="blue_Right_Leg_link" body2="blue_Right_Ankle_link"/>
    <exclude body1="blue_root" body2="blue_Right_Feet_link"/>
    <exclude body1="blue_Right_Lateral_Thigh_link" body2="blue_Right_Feet_link"/>
    <exclude body1="blue_Right_Thigh_link" body2="blue_Right_Feet_link"/>
    <exclude body1="blue_Right_Leg_link" body2="blue_Right_Feet_link"/>
    <exclude body1="blue_Right_Ankle_link" body2="blue_Right_Feet_link"/>
    <exclude body1="blue_root" body2="blue_Right_Shoulder_link"/>
    <exclude body1="blue_root" body2="blue_Right_Arm_link"/>
    <exclude body1="blue_Right_Shoulder_link" body2="blue_Right_Arm_link"/>
    <exclude body1="blue_root" body2="blue_Right_Hand_link"/>
    <exclude body1="blue_Right_Shoulder_link" body2="blue_Right_Hand_link"/>
    <exclude body1="blue_Right_Arm_link" body2="blue_Right_Hand_link"/>
  </contact>

  <worldbody>
    <light pos="0 0 3" dir="0 0 -1" diffuse="0.8 0.8 0.8"/>
    <geom name="floor" size="3 3 0.1" type="plane" material="groundplane"
          condim="3" friction="1 0.1 0.01"/>
    <body name="red_root" pos="-0.5 0 0.298" quat="1.000000 0.000000 0.000000 0.000000">
      <freejoint name="red_freejoint"/>
      <geom name="red_Body_link_col0" type="box" size="0.045 0.0525 0.0535" pos="0.0 0.0 0.0" quat="1.000000 0.000000 0.000000 0.000000" rgba="0.85 0.15 0.15 1" condim="3"/>
      <inertial pos="0.0 0.0 0.0" mass="0.42" diaginertia="0.00078659 0.000684215 0.000669375"/>
      <body name="red_Head_link" pos="0.0 0.0 0.0855" quat="1.000000 0.000000 0.000000 0.000000">
        <geom name="red_Head_link_col0" type="sphere" size="0.045" pos="0.0 0.0 0.0" condim="3"/>
        <inertial pos="0.0 0.0 0.0" mass="0.066" diaginertia="3.7125e-05 3.7125e-05 3.7125e-05"/>
      </body>
      <body name="red_Left_Lateral_Thigh_link" pos="0.0025 0.03 -0.0535" quat="0.707105 0.000000 0.707108 0.000000">
        <joint name="red_Left_Lateral_Thigh_link_joint" type="hinge" axis="0.0 0.0 1.0" range="-1.0 1.93" frictionloss="0.15"/>
        <geom name="red_Left_Lateral_Thigh_link_col0" type="box" size="0.02 0.02 0.02" pos="0.02 0.0 0.0" quat="0.707105 0.000000 -0.707108 0.000000" condim="3"/>
        <inertial pos="0.0 0.0 0.0" mass="0.07" diaginertia="1.8667e-05 1.8667e-05 1.8667e-05"/>
        <body name="red_Left_Thigt_link" pos="0.0395 0.0 0.0" quat="0.499998 0.500000 -0.500000 0.500002">
          <joint name="red_Left_Thigt_link_joint" type="hinge" axis="0.0 0.0 1.0" range="-1.57 1.57" frictionloss="0.15"/>
          <geom name="red_Left_Thigt_link_col0" type="box" size="0.0175 0.02 0.0375" pos="0.0 -0.0375 0.0" quat="0.707105 -0.707108 0.000000 0.000000" condim="3"/>
          <inertial pos="0.0 0.0 0.0" mass="0.115" diaginertia="6.924e-05 6.5646e-05 2.7073e-05"/>
          <body name="red_Left_Leg_Link" pos="0.0 -0.075 0.0" quat="1.000000 0.000000 0.000000 0.000000">
            <joint name="red_Left_Leg_Link_joint" type="hinge" axis="0.0 0.0 1.0" range="-2.3 0.7" frictionloss="0.15"/>
            <geom name="red_Left_Leg_Link_col0" type="box" size="0.0175 0.025 0.03" pos="0.0 -0.03 0.0" quat="0.707105 -0.707108 0.000000 0.000000" condim="3"/>
            <inertial pos="0.0 0.0 0.0" mass="0.11" diaginertia="5.5917e-05 4.4229e-05 3.4146e-05"/>
            <body name="red_Left_Ankle_link" pos="0.0 -0.06 0.0" quat="1.000000 0.000000 0.000000 0.000000">
              <joint name="red_Right_Ankle_link_joint" type="hinge" axis="0.0 0.0 1.0" range="-1.57 1.57" frictionloss="0.15"/>
              <geom name="red_Left_Ankle_link_col0" type="box" size="0.0175 0.02 0.021" pos="0.0 -0.021 0.0" quat="0.707105 -0.707108 0.000000 0.000000" condim="3"/>
              <inertial pos="0.0 0.0 0.0" mass="0.055" diaginertia="1.5418e-05 1.37e-05 1.2948e-05"/>
              <body name="red_Left_Feet_link" pos="0.0 -0.047 0.0" quat="0.499998 -0.500000 0.500002 -0.500000">
                <joint name="red_Left_Feet_link_joint" type="hinge" axis="0.0 0.0 1.0" range="-1.57 0.43" frictionloss="0.15"/>
                <geom name="red_Left_Feet_link_col0" type="box" size="0.055 0.04 0.014" pos="0.009 0.016 0.0" quat="-0.707108 0.000002 0.707105 0.000002" condim="3"/>
                <inertial pos="0.0 0.0 0.0" mass="0.07" diaginertia="4.1907e-05 7.5157e-05 0.000107917"/>
              </body>
            </body>
          </body>
        </body>
      </body>
      <body name="red_Left_Shoulder_link" pos="0.012 0.0525 0.0335" quat="0.707105 0.707108 0.000000 0.000000">
        <joint name="red_Left_Shoulder_link_joint" type="hinge" axis="0.0 0.0 1.0" range="0.0 3.1416" frictionloss="0.15"/>
        <geom name="red_Left_Shoulder_link_col0" type="box" size="0.02 0.01 0.02" pos="0.0 -0.0 -0.01" quat="0.707105 -0.707108 0.000000 0.000000" condim="3"/>
        <inertial pos="0.0 0.0 0.0" mass="0.06" diaginertia="1e-05 1.6e-05 1e-05"/>
        <body name="red_Left_Arm_link" pos="0.0 -0.0 -0.02" quat="0.499998 -0.500000 0.500002 -0.500000">
          <joint name="red_Left_Arm_link_joint" type="hinge" axis="0.0 0.0 1.0" range="-1.57 1.57" frictionloss="0.15"/>
          <geom name="red_Left_Arm_link_col0" type="box" size="0.02 0.03 0.0175" pos="0.0 0.03 0.0" quat="0.707105 0.000000 -0.707108 0.000000" condim="3"/>
          <inertial pos="0.0 0.0 0.0" mass="0.0475" diaginertia="1.9099e-05 1.1182e-05 2.0583e-05"/>
          <body name="red_Left_Hand_link" pos="0.0 0.06 0.0" quat="1.000000 0.000000 0.000000 0.000000">
            <joint name="red_Left_Hand_link_joint" type="hinge" axis="0.0 0.0 1.0" range="-1.57 1.57" frictionloss="0.15"/>
            <geom name="red_Left_Hand_link_col0" type="box" size="0.02 0.0425 0.0175" pos="0.0 0.0425 0.0" quat="0.707105 0.000000 -0.707108 0.000000" condim="3"/>
            <inertial pos="0.0 0.0 0.0" mass="0.02" diaginertia="1.4083e-05 4.708e-06 1.4708e-05"/>
          </body>
        </body>
      </body>
      <body name="red_Right_Lateral_Thigh_link" pos="0.0025 -0.03 -0.0535" quat="0.707105 0.000000 0.707108 0.000000">
        <joint name="red_Right_Lateral_Thigh_link_joint" type="hinge" axis="0.0 0.0 1.0" range="-1.93 1.0" frictionloss="0.15"/>
        <geom name="red_Right_Lateral_Thigh_link_col0" type="box" size="0.02 0.02 0.02" pos="0.02 0.0 0.0" quat="0.707105 0.000000 -0.707108 0.000000" condim="3"/>
        <inertial pos="0.0 0.0 0.0" mass="0.07" diaginertia="1.8667e-05 1.8667e-05 1.8667e-05"/>
        <body name="red_Right_Thigh_link" pos="0.0395 0.0 0.0" quat="0.499998 0.500000 -0.500000 0.500002">
          <joint name="red_Right_Thigh_link_joint" type="hinge" axis="0.0 0.0 1.0" range="-1.57 1.57" frictionloss="0.15"/>
          <geom name="red_Right_Thigh_link_col0" type="box" size="0.0175 0.02 0.0375" pos="0.0 -0.0375 0.0" quat="0.707105 -0.707108 0.000000 0.000000" condim="3"/>
          <inertial pos="0.0 0.0 0.0" mass="0.115" diaginertia="6.924e-05 6.5646e-05 2.7073e-05"/>
          <body name="red_Right_Leg_link" pos="0.0 -0.075 0.0" quat="1.000000 0.000000 0.000000 0.000000">
            <joint name="red_Right_Leg_link_joint" type="hinge" axis="0.0 0.0 1.0" range="-2.3 0.7" frictionloss="0.15"/>
            <geom name="red_Right_Leg_link_col0" type="box" size="0.0175 0.025 0.03" pos="0.0 -0.03 0.0" quat="0.707105 -0.707108 0.000000 0.000000" condim="3"/>
            <inertial pos="0.0 0.0 0.0" mass="0.11" diaginertia="5.5917e-05 4.4229e-05 3.4146e-05"/>
            <body name="red_Right_Ankle_link" pos="0.0 -0.06 0.0" quat="1.000000 0.000000 0.000000 0.000000">
              <joint name="red_Right_ankle_link_joint" type="hinge" axis="0.0 0.0 1.0" range="-1.57 1.57" frictionloss="0.15"/>
              <geom name="red_Right_Ankle_link_col0" type="box" size="0.0175 0.02 0.021" pos="0.0 -0.021 0.0" quat="0.707105 -0.707108 0.000000 0.000000" condim="3"/>
              <inertial pos="0.0 0.0 0.0" mass="0.055" diaginertia="1.5418e-05 1.37e-05 1.2948e-05"/>
              <body name="red_Right_Feet_link" pos="0.0 -0.047 0.0" quat="0.499998 -0.500000 0.500002 -0.500000">
                <joint name="red_Right_Feet_link_joint" type="hinge" axis="0.0 0.0 1.0" range="-0.43 1.57" frictionloss="0.15"/>
                <geom name="red_Right_Feet_link_col0" type="box" size="0.055 0.04 0.014" pos="0.009 -0.016 0.0" quat="-0.707108 0.000002 0.707105 0.000002" condim="3"/>
                <inertial pos="0.0 0.0 0.0" mass="0.07" diaginertia="4.1907e-05 7.5157e-05 0.000107917"/>
              </body>
            </body>
          </body>
        </body>
      </body>
      <body name="red_Right_Shoulder_link" pos="0.012 -0.0525 0.0335" quat="0.707105 0.707108 0.000000 0.000000">
        <joint name="red_Right_Shoulder_link_joint" type="hinge" axis="0.0 0.0 1.0" range="0.0 3.1416" frictionloss="0.15"/>
        <geom name="red_Right_Shoulder_link_col0" type="box" size="0.02 0.01 0.02" pos="0.0 0.0 0.01" quat="0.707105 -0.707108 0.000000 0.000000" condim="3"/>
        <inertial pos="0.0 0.0 0.0" mass="0.06" diaginertia="1e-05 1.6e-05 1e-05"/>
        <body name="red_Right_Arm_link" pos="0.0 0.0 0.02" quat="0.499998 -0.500000 0.500002 -0.500000">
          <joint name="red_Right_Arm_link_joint" type="hinge" axis="0.0 0.0 1.0" range="-1.57 1.57" frictionloss="0.15"/>
          <geom name="red_Right_Arm_link_col0" type="box" size="0.02 0.03 0.0175" pos="0.0 -0.03 0.0" quat="0.707105 0.000000 -0.707108 0.000000" condim="3"/>
          <inertial pos="0.0 0.0 0.0" mass="0.0475" diaginertia="1.9099e-05 1.1182e-05 2.0583e-05"/>
          <body name="red_Right_Hand_link" pos="0.0 -0.06 0.0" quat="1.000000 0.000000 0.000000 0.000000">
            <joint name="red_Right_Hand_link_joint" type="hinge" axis="0.0 0.0 1.0" range="-1.57 1.57" frictionloss="0.15"/>
            <geom name="red_Right_Hand_link_col0" type="box" size="0.02 0.0425 0.0175" pos="0.0 -0.0425 0.0" quat="0.707105 0.000000 -0.707108 0.000000" condim="3"/>
            <inertial pos="0.0 0.0 0.0" mass="0.02" diaginertia="1.4083e-05 4.708e-06 1.4708e-05"/>
          </body>
        </body>
      </body>
    </body>
    <body name="blue_root" pos="0.5 0 0.298" quat="0.000001 0.000000 0.000000 1.000000">
      <freejoint name="blue_freejoint"/>
      <geom name="blue_Body_link_col0" type="box" size="0.045 0.0525 0.0535" pos="0.0 0.0 0.0" quat="1.000000 0.000000 0.000000 0.000000" rgba="0.15 0.15 0.85 1" condim="3"/>
      <inertial pos="0.0 0.0 0.0" mass="0.42" diaginertia="0.00078659 0.000684215 0.000669375"/>
      <body name="blue_Head_link" pos="0.0 0.0 0.0855" quat="1.000000 0.000000 0.000000 0.000000">
        <geom name="blue_Head_link_col0" type="sphere" size="0.045" pos="0.0 0.0 0.0" condim="3"/>
        <inertial pos="0.0 0.0 0.0" mass="0.066" diaginertia="3.7125e-05 3.7125e-05 3.7125e-05"/>
      </body>
      <body name="blue_Left_Lateral_Thigh_link" pos="0.0025 0.03 -0.0535" quat="0.707105 0.000000 0.707108 0.000000">
        <joint name="blue_Left_Lateral_Thigh_link_joint" type="hinge" axis="0.0 0.0 1.0" range="-1.0 1.93" frictionloss="0.15"/>
        <geom name="blue_Left_Lateral_Thigh_link_col0" type="box" size="0.02 0.02 0.02" pos="0.02 0.0 0.0" quat="0.707105 0.000000 -0.707108 0.000000" condim="3"/>
        <inertial pos="0.0 0.0 0.0" mass="0.07" diaginertia="1.8667e-05 1.8667e-05 1.8667e-05"/>
        <body name="blue_Left_Thigt_link" pos="0.0395 0.0 0.0" quat="0.499998 0.500000 -0.500000 0.500002">
          <joint name="blue_Left_Thigt_link_joint" type="hinge" axis="0.0 0.0 1.0" range="-1.57 1.57" frictionloss="0.15"/>
          <geom name="blue_Left_Thigt_link_col0" type="box" size="0.0175 0.02 0.0375" pos="0.0 -0.0375 0.0" quat="0.707105 -0.707108 0.000000 0.000000" condim="3"/>
          <inertial pos="0.0 0.0 0.0" mass="0.115" diaginertia="6.924e-05 6.5646e-05 2.7073e-05"/>
          <body name="blue_Left_Leg_Link" pos="0.0 -0.075 0.0" quat="1.000000 0.000000 0.000000 0.000000">
            <joint name="blue_Left_Leg_Link_joint" type="hinge" axis="0.0 0.0 1.0" range="-2.3 0.7" frictionloss="0.15"/>
            <geom name="blue_Left_Leg_Link_col0" type="box" size="0.0175 0.025 0.03" pos="0.0 -0.03 0.0" quat="0.707105 -0.707108 0.000000 0.000000" condim="3"/>
            <inertial pos="0.0 0.0 0.0" mass="0.11" diaginertia="5.5917e-05 4.4229e-05 3.4146e-05"/>
            <body name="blue_Left_Ankle_link" pos="0.0 -0.06 0.0" quat="1.000000 0.000000 0.000000 0.000000">
              <joint name="blue_Right_Ankle_link_joint" type="hinge" axis="0.0 0.0 1.0" range="-1.57 1.57" frictionloss="0.15"/>
              <geom name="blue_Left_Ankle_link_col0" type="box" size="0.0175 0.02 0.021" pos="0.0 -0.021 0.0" quat="0.707105 -0.707108 0.000000 0.000000" condim="3"/>
              <inertial pos="0.0 0.0 0.0" mass="0.055" diaginertia="1.5418e-05 1.37e-05 1.2948e-05"/>
              <body name="blue_Left_Feet_link" pos="0.0 -0.047 0.0" quat="0.499998 -0.500000 0.500002 -0.500000">
                <joint name="blue_Left_Feet_link_joint" type="hinge" axis="0.0 0.0 1.0" range="-1.57 0.43" frictionloss="0.15"/>
                <geom name="blue_Left_Feet_link_col0" type="box" size="0.055 0.04 0.014" pos="0.009 0.016 0.0" quat="-0.707108 0.000002 0.707105 0.000002" condim="3"/>
                <inertial pos="0.0 0.0 0.0" mass="0.07" diaginertia="4.1907e-05 7.5157e-05 0.000107917"/>
              </body>
            </body>
          </body>
        </body>
      </body>
      <body name="blue_Left_Shoulder_link" pos="0.012 0.0525 0.0335" quat="0.707105 0.707108 0.000000 0.000000">
        <joint name="blue_Left_Shoulder_link_joint" type="hinge" axis="0.0 0.0 1.0" range="0.0 3.1416" frictionloss="0.15"/>
        <geom name="blue_Left_Shoulder_link_col0" type="box" size="0.02 0.01 0.02" pos="0.0 -0.0 -0.01" quat="0.707105 -0.707108 0.000000 0.000000" condim="3"/>
        <inertial pos="0.0 0.0 0.0" mass="0.06" diaginertia="1e-05 1.6e-05 1e-05"/>
        <body name="blue_Left_Arm_link" pos="0.0 -0.0 -0.02" quat="0.499998 -0.500000 0.500002 -0.500000">
          <joint name="blue_Left_Arm_link_joint" type="hinge" axis="0.0 0.0 1.0" range="-1.57 1.57" frictionloss="0.15"/>
          <geom name="blue_Left_Arm_link_col0" type="box" size="0.02 0.03 0.0175" pos="0.0 0.03 0.0" quat="0.707105 0.000000 -0.707108 0.000000" condim="3"/>
          <inertial pos="0.0 0.0 0.0" mass="0.0475" diaginertia="1.9099e-05 1.1182e-05 2.0583e-05"/>
          <body name="blue_Left_Hand_link" pos="0.0 0.06 0.0" quat="1.000000 0.000000 0.000000 0.000000">
            <joint name="blue_Left_Hand_link_joint" type="hinge" axis="0.0 0.0 1.0" range="-1.57 1.57" frictionloss="0.15"/>
            <geom name="blue_Left_Hand_link_col0" type="box" size="0.02 0.0425 0.0175" pos="0.0 0.0425 0.0" quat="0.707105 0.000000 -0.707108 0.000000" condim="3"/>
            <inertial pos="0.0 0.0 0.0" mass="0.02" diaginertia="1.4083e-05 4.708e-06 1.4708e-05"/>
          </body>
        </body>
      </body>
      <body name="blue_Right_Lateral_Thigh_link" pos="0.0025 -0.03 -0.0535" quat="0.707105 0.000000 0.707108 0.000000">
        <joint name="blue_Right_Lateral_Thigh_link_joint" type="hinge" axis="0.0 0.0 1.0" range="-1.93 1.0" frictionloss="0.15"/>
        <geom name="blue_Right_Lateral_Thigh_link_col0" type="box" size="0.02 0.02 0.02" pos="0.02 0.0 0.0" quat="0.707105 0.000000 -0.707108 0.000000" condim="3"/>
        <inertial pos="0.0 0.0 0.0" mass="0.07" diaginertia="1.8667e-05 1.8667e-05 1.8667e-05"/>
        <body name="blue_Right_Thigh_link" pos="0.0395 0.0 0.0" quat="0.499998 0.500000 -0.500000 0.500002">
          <joint name="blue_Right_Thigh_link_joint" type="hinge" axis="0.0 0.0 1.0" range="-1.57 1.57" frictionloss="0.15"/>
          <geom name="blue_Right_Thigh_link_col0" type="box" size="0.0175 0.02 0.0375" pos="0.0 -0.0375 0.0" quat="0.707105 -0.707108 0.000000 0.000000" condim="3"/>
          <inertial pos="0.0 0.0 0.0" mass="0.115" diaginertia="6.924e-05 6.5646e-05 2.7073e-05"/>
          <body name="blue_Right_Leg_link" pos="0.0 -0.075 0.0" quat="1.000000 0.000000 0.000000 0.000000">
            <joint name="blue_Right_Leg_link_joint" type="hinge" axis="0.0 0.0 1.0" range="-2.3 0.7" frictionloss="0.15"/>
            <geom name="blue_Right_Leg_link_col0" type="box" size="0.0175 0.025 0.03" pos="0.0 -0.03 0.0" quat="0.707105 -0.707108 0.000000 0.000000" condim="3"/>
            <inertial pos="0.0 0.0 0.0" mass="0.11" diaginertia="5.5917e-05 4.4229e-05 3.4146e-05"/>
            <body name="blue_Right_Ankle_link" pos="0.0 -0.06 0.0" quat="1.000000 0.000000 0.000000 0.000000">
              <joint name="blue_Right_ankle_link_joint" type="hinge" axis="0.0 0.0 1.0" range="-1.57 1.57" frictionloss="0.15"/>
              <geom name="blue_Right_Ankle_link_col0" type="box" size="0.0175 0.02 0.021" pos="0.0 -0.021 0.0" quat="0.707105 -0.707108 0.000000 0.000000" condim="3"/>
              <inertial pos="0.0 0.0 0.0" mass="0.055" diaginertia="1.5418e-05 1.37e-05 1.2948e-05"/>
              <body name="blue_Right_Feet_link" pos="0.0 -0.047 0.0" quat="0.499998 -0.500000 0.500002 -0.500000">
                <joint name="blue_Right_Feet_link_joint" type="hinge" axis="0.0 0.0 1.0" range="-0.43 1.57" frictionloss="0.15"/>
                <geom name="blue_Right_Feet_link_col0" type="box" size="0.055 0.04 0.014" pos="0.009 -0.016 0.0" quat="-0.707108 0.000002 0.707105 0.000002" condim="3"/>
                <inertial pos="0.0 0.0 0.0" mass="0.07" diaginertia="4.1907e-05 7.5157e-05 0.000107917"/>
              </body>
            </body>
          </body>
        </body>
      </body>
      <body name="blue_Right_Shoulder_link" pos="0.012 -0.0525 0.0335" quat="0.707105 0.707108 0.000000 0.000000">
        <joint name="blue_Right_Shoulder_link_joint" type="hinge" axis="0.0 0.0 1.0" range="0.0 3.1416" frictionloss="0.15"/>
        <geom name="blue_Right_Shoulder_link_col0" type="box" size="0.02 0.01 0.02" pos="0.0 0.0 0.01" quat="0.707105 -0.707108 0.000000 0.000000" condim="3"/>
        <inertial pos="0.0 0.0 0.0" mass="0.06" diaginertia="1e-05 1.6e-05 1e-05"/>
        <body name="blue_Right_Arm_link" pos="0.0 0.0 0.02" quat="0.499998 -0.500000 0.500002 -0.500000">
          <joint name="blue_Right_Arm_link_joint" type="hinge" axis="0.0 0.0 1.0" range="-1.57 1.57" frictionloss="0.15"/>
          <geom name="blue_Right_Arm_link_col0" type="box" size="0.02 0.03 0.0175" pos="0.0 -0.03 0.0" quat="0.707105 0.000000 -0.707108 0.000000" condim="3"/>
          <inertial pos="0.0 0.0 0.0" mass="0.0475" diaginertia="1.9099e-05 1.1182e-05 2.0583e-05"/>
          <body name="blue_Right_Hand_link" pos="0.0 -0.06 0.0" quat="1.000000 0.000000 0.000000 0.000000">
            <joint name="blue_Right_Hand_link_joint" type="hinge" axis="0.0 0.0 1.0" range="-1.57 1.57" frictionloss="0.15"/>
            <geom name="blue_Right_Hand_link_col0" type="box" size="0.02 0.0425 0.0175" pos="0.0 -0.0425 0.0" quat="0.707105 0.000000 -0.707108 0.000000" condim="3"/>
            <inertial pos="0.0 0.0 0.0" mass="0.02" diaginertia="1.4083e-05 4.708e-06 1.4708e-05"/>
          </body>
        </body>
      </body>
    </body>
  </worldbody>

  <actuator>
    <position name="act_red_Left_Lateral_Thigh_link_joint" joint="red_Left_Lateral_Thigh_link_joint" kp="8" kv="10" ctrlrange="-1.0 1.93" forcerange="-1.5 1.5"/>
    <position name="act_red_Left_Thigt_link_joint" joint="red_Left_Thigt_link_joint" kp="8" kv="10" ctrlrange="-1.57 1.57" forcerange="-1.5 1.5"/>
    <position name="act_red_Left_Leg_Link_joint" joint="red_Left_Leg_Link_joint" kp="8" kv="10" ctrlrange="-2.3 0.7" forcerange="-1.5 1.5"/>
    <position name="act_red_Right_Ankle_link_joint" joint="red_Right_Ankle_link_joint" kp="8" kv="10" ctrlrange="-1.57 1.57" forcerange="-1.5 1.5"/>
    <position name="act_red_Left_Feet_link_joint" joint="red_Left_Feet_link_joint" kp="8" kv="10" ctrlrange="-1.57 0.43" forcerange="-1.5 1.5"/>
    <position name="act_red_Left_Shoulder_link_joint" joint="red_Left_Shoulder_link_joint" kp="8" kv="10" ctrlrange="0.0 3.1416" forcerange="-1.5 1.5"/>
    <position name="act_red_Left_Arm_link_joint" joint="red_Left_Arm_link_joint" kp="8" kv="10" ctrlrange="-1.57 1.57" forcerange="-1.5 1.5"/>
    <position name="act_red_Left_Hand_link_joint" joint="red_Left_Hand_link_joint" kp="8" kv="10" ctrlrange="-1.57 1.57" forcerange="-1.5 1.5"/>
    <position name="act_red_Right_Lateral_Thigh_link_joint" joint="red_Right_Lateral_Thigh_link_joint" kp="8" kv="10" ctrlrange="-1.93 1.0" forcerange="-1.5 1.5"/>
    <position name="act_red_Right_Thigh_link_joint" joint="red_Right_Thigh_link_joint" kp="8" kv="10" ctrlrange="-1.57 1.57" forcerange="-1.5 1.5"/>
    <position name="act_red_Right_Leg_link_joint" joint="red_Right_Leg_link_joint" kp="8" kv="10" ctrlrange="-2.3 0.7" forcerange="-1.5 1.5"/>
    <position name="act_red_Right_ankle_link_joint" joint="red_Right_ankle_link_joint" kp="8" kv="10" ctrlrange="-1.57 1.57" forcerange="-1.5 1.5"/>
    <position name="act_red_Right_Feet_link_joint" joint="red_Right_Feet_link_joint" kp="8" kv="10" ctrlrange="-0.43 1.57" forcerange="-1.5 1.5"/>
    <position name="act_red_Right_Shoulder_link_joint" joint="red_Right_Shoulder_link_joint" kp="8" kv="10" ctrlrange="0.0 3.1416" forcerange="-1.5 1.5"/>
    <position name="act_red_Right_Arm_link_joint" joint="red_Right_Arm_link_joint" kp="8" kv="10" ctrlrange="-1.57 1.57" forcerange="-1.5 1.5"/>
    <position name="act_red_Right_Hand_link_joint" joint="red_Right_Hand_link_joint" kp="8" kv="10" ctrlrange="-1.57 1.57" forcerange="-1.5 1.5"/>
    <position name="act_blue_Left_Lateral_Thigh_link_joint" joint="blue_Left_Lateral_Thigh_link_joint" kp="8" kv="10" ctrlrange="-1.0 1.93" forcerange="-1.5 1.5"/>
    <position name="act_blue_Left_Thigt_link_joint" joint="blue_Left_Thigt_link_joint" kp="8" kv="10" ctrlrange="-1.57 1.57" forcerange="-1.5 1.5"/>
    <position name="act_blue_Left_Leg_Link_joint" joint="blue_Left_Leg_Link_joint" kp="8" kv="10" ctrlrange="-2.3 0.7" forcerange="-1.5 1.5"/>
    <position name="act_blue_Right_Ankle_link_joint" joint="blue_Right_Ankle_link_joint" kp="8" kv="10" ctrlrange="-1.57 1.57" forcerange="-1.5 1.5"/>
    <position name="act_blue_Left_Feet_link_joint" joint="blue_Left_Feet_link_joint" kp="8" kv="10" ctrlrange="-1.57 0.43" forcerange="-1.5 1.5"/>
    <position name="act_blue_Left_Shoulder_link_joint" joint="blue_Left_Shoulder_link_joint" kp="8" kv="10" ctrlrange="0.0 3.1416" forcerange="-1.5 1.5"/>
    <position name="act_blue_Left_Arm_link_joint" joint="blue_Left_Arm_link_joint" kp="8" kv="10" ctrlrange="-1.57 1.57" forcerange="-1.5 1.5"/>
    <position name="act_blue_Left_Hand_link_joint" joint="blue_Left_Hand_link_joint" kp="8" kv="10" ctrlrange="-1.57 1.57" forcerange="-1.5 1.5"/>
    <position name="act_blue_Right_Lateral_Thigh_link_joint" joint="blue_Right_Lateral_Thigh_link_joint" kp="8" kv="10" ctrlrange="-1.93 1.0" forcerange="-1.5 1.5"/>
    <position name="act_blue_Right_Thigh_link_joint" joint="blue_Right_Thigh_link_joint" kp="8" kv="10" ctrlrange="-1.57 1.57" forcerange="-1.5 1.5"/>
    <position name="act_blue_Right_Leg_link_joint" joint="blue_Right_Leg_link_joint" kp="8" kv="10" ctrlrange="-2.3 0.7" forcerange="-1.5 1.5"/>
    <position name="act_blue_Right_ankle_link_joint" joint="blue_Right_ankle_link_joint" kp="8" kv="10" ctrlrange="-1.57 1.57" forcerange="-1.5 1.5"/>
    <position name="act_blue_Right_Feet_link_joint" joint="blue_Right_Feet_link_joint" kp="8" kv="10" ctrlrange="-0.43 1.57" forcerange="-1.5 1.5"/>
    <position name="act_blue_Right_Shoulder_link_joint" joint="blue_Right_Shoulder_link_joint" kp="8" kv="10" ctrlrange="0.0 3.1416" forcerange="-1.5 1.5"/>
    <position name="act_blue_Right_Arm_link_joint" joint="blue_Right_Arm_link_joint" kp="8" kv="10" ctrlrange="-1.57 1.57" forcerange="-1.5 1.5"/>
    <position name="act_blue_Right_Hand_link_joint" joint="blue_Right_Hand_link_joint" kp="8" kv="10" ctrlrange="-1.57 1.57" forcerange="-1.5 1.5"/>
  </actuator>

</mujoco>
