<robot name="Robot" version="1.0">
  <joint name="Head_link_joint" type="fixed">
    <origin rpy="0.00000 0.00000 0.00000" xyz="0.00000 0.00000 0.08550"/>
    <parent link="Body_link"/>
    <child link="Head_link"/>
  </joint>
  <joint name="Left_Arm_link_joint" type="revolute">
    <limit lower="-1.57000" upper="1.57000" effort="1.2" velocity="5.2"/>
    <origin rpy="-1.57080 -0.00000 -1.57080" xyz="0.00000 -0.00000 -0.02000"/>
    <parent link="Left_Shoulder_link"/>
    <child link="Left_Arm_link"/>
    <axis xyz="0.00000 0.00000 1.00000"/>
    <dynamics damping="0.04" friction="0.15"/>
  </joint>
  <joint name="Left_Feet_link_joint" type="revolute">
    <limit lower="-1.57000" upper="0.43000" effort="1.2" velocity="5.2"/>
    <origin rpy="-1.57080 -0.00000 -1.57080" xyz="0.00000 -0.04700 0.00000"/>
    <parent link="Left_Ankle_link"/>
    <child link="Left_Feet_link"/>
    <axis xyz="0.00000 0.00000 1.00000"/>
    <dynamics damping="0.04" friction="0.15"/>
  </joint>
  <joint name="Left_Hand_link_joint" type="revolute">
    <limit lower="-1.57000" upper="1.57000" effort="1.2" velocity="5.2"/>
    <origin rpy="-0.00000 0.00000 0.00000" xyz="0.00000 0.06000 0.00000"/>
    <parent link="Left_Arm_link"/>
    <child link="Left_Hand_link"/>
    <axis xyz="0.00000 0.00000 1.00000"/>
    <dynamics damping="0.04" friction="0.15"/>
  </joint>
  <joint name="Left_Lateral_Thigh_link_joint" type="revolute">
    <limit lower="-1" upper="1.93000" effort="1.2" velocity="5.2"/>
    <origin rpy="-0.00000 1.57080 0.00000" xyz="0.00250 0.03000 -0.05350"/>
    <parent link="Body_link"/>
    <child link="Left_Lateral_Thigh_link"/>
    <axis xyz="0.00000 0.00000 1.00000"/>
    <dynamics damping="0.04" friction="0.15"/>
  </joint>
  <joint name="Left_Leg_Link_joint" type="revolute">
    <limit lower="-2.7000" upper="0.3000" effort="1.2" velocity="5.2"/>
    <origin rpy="0.00000 0.00000 0.00000" xyz="-0.0250000 -0.0500 0.00000"/>
    <parent link="Left_Thigt_link"/>
    <child link="Left_Leg_Link"/>
    <axis xyz="0.00000 0.00000 1.00000"/>
    <dynamics damping="0.04" friction="0.15"/>
  </joint>
  <joint name="Left_Shoulder_link_joint" type="revolute">
    <limit lower="0" upper="3.1416" effort="1.2" velocity="5.2"/>
    <origin rpy="1.57080 0.00000 0.00000" xyz="0.01200 0.05250 0.03350"/>
    <parent link="Body_link"/>
    <child link="Left_Shoulder_link"/>
    <axis xyz="0.00000 0.00000 1.00000"/>
    <dynamics damping="0.04" friction="0.15"/>
  </joint>
  <joint name="Left_Thigt_link_joint" type="revolute">
    <limit lower="-1.57000" upper="1.57" effort="1.2" velocity="5.2"/>
    <origin rpy="1.57080 -1.57080 0.00000" xyz="0.04450 0.00000 0.00000"/>
    <parent link="Left_Lateral_Thigh_link"/>
    <child link="Left_Thigt_link"/>
    <axis xyz="0.00000 0.00000 1.00000"/>
    <dynamics damping="0.04" friction="0.15"/>
  </joint>
  <joint name="Right_Ankle_link_joint" type="revolute">
    <limit lower="-1.57000" upper="1.57000" effort="1.2" velocity="5.2"/>
    <origin rpy="0.00000 0.00000 0.00000" xyz="0.00000 -0.06000 0.00000"/>
    <parent link="Left_Leg_Link"/>
    <child link="Left_Ankle_link"/>
    <axis xyz="0.00000 0.00000 1.00000"/>
    <dynamics damping="0.04" friction="0.15"/>
  </joint>
  <joint name="Right_Arm_link_joint" type="revolute">
    <limit lower="-1.57000" upper="1.57000" effort="1.2" velocity="5.2"/>
    <origin rpy="-1.57080 -0.00000 -1.57080" xyz="0.00000 0.00000 0.02000"/>
    <parent link="Right_Shoulder_link"/>
    <child link="Right_Arm_link"/>
    <axis xyz="0.00000 0.00000 1.00000"/>
    <dynamics damping="0.04" friction="0.15"/>
  </joint>
  <joint name="Right_Feet_link_joint" type="revolute">
    <limit lower="-0.43000" upper="1.57000" effort="1.2" velocity="5.2"/>
    <origin rpy="-1.57080 -0.00000 -1.57080" xyz="0.00000 -0.04700 0.00000"/>
    <parent link="Right_Ankle_link"/>
    <child link="Right_Feet_link"/>
    <axis xyz="0.00000 0.00000 1.00000"/>
    <dynamics damping="0.04" friction="0.15"/>
  </joint>
  <joint name="Right_Hand_link_joint" type="revolute">
    <limit lower="-1.57000" upper="1.57000" effort="1.2" velocity="5.2"/>
    <origin rpy="-0.00000 0.00000 0.00000" xyz="0.00000 -0.06000 0.00000"/>
    <parent link="Right_Arm_link"/>
    <child link="Right_Hand_link"/>
    <axis xyz="0.00000 0.00000 1.00000"/>
    <dynamics damping="0.04" friction="0.15"/>
  </joint>
  <joint name="Right_Lateral_Thigh_link_joint" type="revolute">
    <limit lower="-1.93" upper="1" effort="1.2" velocity="5.2"/>
    <origin rpy="-0.00000 1.57080 0.00000" xyz="0.00250 -0.03000 -0.05350"/>
    <parent link="Body_link"/>
    <child link="Right_Lateral_Thigh_link"/>
    <axis xyz="0.00000 0.00000 1.00000"/>
    <dynamics damping="0.04" friction="0.15"/>
  </joint>
  <joint name="Right_Leg_link_joint" type="revolute">
    <limit lower="-2.7000" upper="0.3000" effort="1.2" velocity="5.2"/>
    <origin rpy="0.00000 0.00000 0.00000" xyz="-0.02500 -0.0500 0.00000"/>
    <parent link="Right_Thigh_link"/>
    <child link="Right_Leg_link"/>
    <axis xyz="0.00000 0.00000 1.00000"/>
    <dynamics damping="0.04" friction="0.15"/>
  </joint>
  <joint name="Right_Shoulder_link_joint" type="revolute">
    <limit lower="0" upper="3.1416" effort="1.2" velocity="5.2"/>
    <origin rpy="1.57080 0.00000 0.00000" xyz="0.01200 -0.05250 0.03350"/>
    <parent link="Body_link"/>
    <child link="Right_Shoulder_link"/>
    <axis xyz="0.00000 0.00000 1.00000"/>
    <dynamics damping="0.04" friction="0.15"/>
  </joint>
  <joint name="Right_Thigh_link_joint" type="revolute">
    <limit lower="-1.57000" upper="1.57000" effort="1.2" velocity="5.2"/>
    <origin rpy="1.57080 -1.57080 0.00000" xyz="0.04450 0.00000 0.00000"/>
    <parent link="Right_Lateral_Thigh_link"/>
    <child link="Right_Thigh_link"/>
    <axis xyz="0.00000 0.00000 1.00000"/>
    <dynamics damping="0.04" friction="0.15"/>
  </joint>
  <joint name="Right_ankle_link_joint" type="revolute">
    <limit lower="-1.57000" upper="1.57000" effort="1.2" velocity="5.2"/>
    <origin rpy="0.00000 0.00000 0.00000" xyz="0.00000 -0.06000 0.00000"/>
    <parent link="Right_Leg_link"/>
    <child link="Right_Ankle_link"/>
    <axis xyz="0.00000 0.00000 1.00000"/>
    <dynamics damping="0.04" friction="0.15"/>
  </joint>
  <link name="Body_link">
    <collision name="Body_collision">
      <origin rpy="0.00000 0.00000 0.00000" xyz="0.00000 0.00000 0.00000"/>
      <geometry>
        <box size="0.09000 0.10500 0.10700"/>
      </geometry>
    </collision>
    <visual name="Body">
      <origin rpy="0.00000 0.00000 0.00000" xyz="0.00000 0.00000 0.00000"/>
      <material name="Material"/>
      <geometry>
        <box size="0.09000 0.10500 0.10700"/>
      </geometry>
    </visual>
    <inertial>
      <origin xyz="0 0 0"/>
      <mass value="0.42"/>
      <inertia ixx="0.00078659" ixy="0" ixz="0"
              iyy="0.000684215" iyz="0"
              izz="0.000669375"/>
    </inertial>
  </link>
  <link name="Head_link">
    <collision name="Head_collision">
      <origin rpy="0.00000 0.00000 0.00000" xyz="0.00000 0.00000 0.00000"/>
      <geometry>
        <sphere radius="0.04500"/>
      </geometry>
    </collision>
    <visual name="Head">
      <origin rpy="0.00000 0.00000 0.00000" xyz="0.00000 0.00000 0.00000"/>
      <material name="Material.001"/>
      <geometry>
        <sphere radius="0.03750"/>
      </geometry>
    </visual>
    <inertial>
      <origin xyz="0 0 0"/>
      <mass value="0.066"/>
      <inertia ixx="0.000037125" ixy="0.0" ixz="0.0"
              iyy="0.000037125" iyz="0.0"
              izz="0.000037125"/>
    </inertial>
  </link>
  <link name="Left_Ankle_link">
    <collision name="Right_Ankle_collision">
      <origin rpy="-1.57080 0.00000 0.00000" xyz="0.00000 -0.02100 0.00000"/>
      <geometry>
        <box size="0.03500 0.04000 0.04200"/>
      </geometry>
    </collision>
    <visual name="Right_Ankle">
      <origin rpy="-1.57080 0.00000 0.00000" xyz="0.00000 -0.02100 0.00000"/>
      <material name="Material.001"/>
      <geometry>
        <box size="0.03500 0.04000 0.04200"/>
      </geometry>
    </visual>
    <inertial>
      <origin xyz="0 0 0"/>
      <mass value="0.055"/>
      <inertia ixx="0.000015418" ixy="0" ixz="0"
              iyy="0.0000137" iyz="0"
              izz="0.000012948"/>
    </inertial>
  </link>
  <link name="Left_Arm_link">
    <collision name="Left_Arm_collision">
      <origin rpy="0.00000 -1.57080 0.00000" xyz="0.00000 0.03000 0.00000"/>
      <geometry>
        <box size="0.04000 0.06000 0.03500"/>
      </geometry>
    </collision>
    <visual name="Left_Arm">
      <origin rpy="0.00000 -1.57080 0.00000" xyz="0.00000 0.03000 0.00000"/>
      <material name="Material.001"/>
      <geometry>
        <box size="0.04000 0.06000 0.03500"/>
      </geometry>
    </visual>
    <inertial>
      <origin xyz="0 0 0"/>
      <mass value="0.0475"/>
      <inertia ixx="0.000019099" ixy="0" ixz="0"
              iyy="0.000011182" iyz="0"
              izz="0.000020583"/>
    </inertial>
  </link>
  <link name="Left_Feet_link">
    <collision name="Right_Feet_collision">
      <origin rpy="3.14159 -1.57080 3.14159" xyz="0.00900 0.01600 0.00000"/>
      <geometry>
        <box size="0.11000 0.08000 0.02800"/>
      </geometry>
    </collision>
    <visual name="Right_Feet">
      <origin rpy="3.14159 -1.57080 3.14159" xyz="0.00900 0.01600 0.00000"/>
      <material name="Material"/>
      <geometry>
        <box size="0.11000 0.08000 0.02800"/>
      </geometry>
    </visual>
    <inertial>
      <origin xyz="0 0 0"/>
      <mass value="0.07"/>
      <inertia ixx="0.000041907" ixy="0" ixz="0"
              iyy="0.000075157" iyz="0"
              izz="0.000107917"/>
    </inertial>
  </link>
  <link name="Left_Hand_link">
    <collision name="Left_Hand_collision">
      <origin rpy="0.00000 -1.57080 0.00000" xyz="0.00000 0.04250 0.00000"/>
      <geometry>
        <box size="0.04000 0.08500 0.03500"/>
      </geometry>
    </collision>
    <visual name="Left_Hand">
      <origin rpy="0.00000 -1.57080 0.00000" xyz="0.00000 0.04250 0.00000"/>
      <material name="Material"/>
      <geometry>
        <box size="0.04000 0.08500 0.03500"/>
      </geometry>
    </visual>
    <inertial>
      <origin xyz="0 0 0"/>
      <mass value="0.02"/>
      <inertia ixx="0.000014083" ixy="0" ixz="0"
              iyy="0.000004708" iyz="0"
              izz="0.000014708"/>
    </inertial>
  </link>
  <link name="Left_Lateral_Thigh_link">
    <collision name="Left_Lateral_Thigh_collision">
      <origin rpy="0.00000 -1.57080 0.00000" xyz="0.0225000 0.00000 0.00000"/>
      <geometry>
        <box size="0.04000 0.04000 0.04500"/>
      </geometry>
    </collision>
    <visual name="Left_Lateral_Thigh">
      <origin rpy="0.00000 -1.57080 0.00000" xyz="0.0225S0 0.00000 0.00000"/>
      <material name="Material.002"/>
      <geometry>
        <box size="0.04000 0.04000 0.04500"/>
      </geometry>
    </visual>
    <inertial>
      <origin xyz="0 0 0"/>
      <mass value="0.07"/>
      <inertia ixx="0.00002114583" ixy="0" ixz="0"
              iyy="0.00002114583" iyz="0"
              izz="0.000018667"/>
    </inertial>
  </link>
  <link name="Left_Leg_Link">
    <collision name="Left_Leg_collision">
      <origin rpy="-1.57080 0.00000 0.00000" xyz="0.00000 -0.03000 0.00000"/>
      <geometry>
        <box size="0.03500 0.05000 0.06000"/>
      </geometry>
    </collision>
    <visual name="Left_Leg">
      <origin rpy="-1.57080 0.00000 0.00000" xyz="0.00000 -0.03000 0.00000"/>
      <material name="Material.002"/>
      <geometry>
        <box size="0.03500 0.05000 0.06000"/>
      </geometry>
    </visual>
    <inertial>
      <origin xyz="0 0 0"/>
      <mass value="0.11"/>
      <inertia ixx="0.000055917" ixy="0" ixz="0"
              iyy="0.000044229" iyz="0"
              izz="0.000034146"/>
    </inertial>
  </link>
  <link name="Left_Shoulder_link">
    <collision name="Left_Shoulder_collision">
      <origin rpy="-1.57080 0.00000 0.00000" xyz="0.00000 -0.00000 -0.01000"/>
      <geometry>
        <box size="0.04000 0.02000 0.04000"/>
      </geometry>
    </collision>
    <visual name="Left_Shoulder">
      <origin rpy="-1.57080 0.00000 0.00000" xyz="0.00000 -0.00000 -0.01000"/>
      <material name="Material.002"/>
      <geometry>
        <box size="0.04000 0.02000 0.04000"/>
      </geometry>
    </visual>
    <inertial>
      <origin xyz="0 0 0"/>
      <mass value="0.06"/>
      <inertia ixx="0.00001" ixy="0" ixz="0"
              iyy="0.000016" iyz="0"
              izz="0.00001"/>
    </inertial>
  </link>
  <link name="Left_Thigt_link">
    <collision name="Left_Thigh_collision">
      <origin rpy="-1.57080 0.00000 0.00000" xyz="0.00000 -0.0250 0.00000"/>
      <geometry>
        <box size="0.03500 0.04000 0.0500"/>
      </geometry>
    </collision>
    <visual name="Left_Thigh">
      <origin rpy="-1.57080 0.00000 0.00000" xyz="0.00000 -0.0250 0.00000"/>
      <material name="Material.001"/>
      <geometry>
        <box size="0.03500 0.04000 0.0500"/>
      </geometry>
    </visual>
    <inertial>
      <origin xyz="0 0 0"/>
      <mass value="0.115"/>
      <inertia ixx="0.00003929166" ixy="0" ixz="0"
              iyy="0.00003569791" iyz="0"
              izz="0.000027073"/>
    </inertial>
  </link>
  <link name="Right_Ankle_link">
    <collision name="Left_Ankle_collision">
      <origin rpy="-1.57080 0.00000 0.00000" xyz="0.00000 -0.02100 0.00000"/>
      <geometry>
        <box size="0.03500 0.04000 0.04200"/>
      </geometry>
    </collision>
    <visual name="Left_Ankle">
      <origin rpy="-1.57080 0.00000 0.00000" xyz="0.00000 -0.02100 0.00000"/>
      <material name="Material.001"/>
      <geometry>
        <box size="0.03500 0.04000 0.04200"/>
      </geometry>
    </visual>
    <inertial>
      <origin xyz="0 0 0"/>
      <mass value="0.055"/>
      <inertia ixx="0.000015418" ixy="0" ixz="0"
              iyy="0.0000137" iyz="0"
              izz="0.000012948"/>
    </inertial>
  </link>
  <link name="Right_Arm_link">
    <collision name="Right_Arm_collision">
      <origin rpy="0.00000 -1.57080 0.00000" xyz="0.00000 -0.03000 0.00000"/>
      <geometry>
        <box size="0.04000 0.06000 0.03500"/>
      </geometry>
    </collision>
    <visual name="Right_Arm">
      <origin rpy="0.00000 -1.57080 0.00000" xyz="0.00000 -0.03000 0.00000"/>
      <material name="Material.001"/>
      <geometry>
        <box size="0.04000 0.06000 0.03500"/>
      </geometry>
    </visual>
    <inertial>
      <origin xyz="0 0 0"/>
      <mass value="0.0475"/>
      <inertia ixx="0.000019099" ixy="0" ixz="0"
              iyy="0.000011182" iyz="0"
              izz="0.000020583"/>
    </inertial>
  </link>
  <link name="Right_Feet_link">
    <collision name="Left_Feet_collision">
      <origin rpy="3.14159 -1.57080 3.14159" xyz="0.00900 -0.01600 0.00000"/>
      <geometry>
        <box size="0.11000 0.08000 0.02800"/>
      </geometry>
    </collision>
    <visual name="Left_Feet">
      <origin rpy="3.14159 -1.57080 3.14159" xyz="0.00900 -0.01600 0.00000"/>
      <material name="Material"/>
      <geometry>
        <box size="0.11000 0.08000 0.02800"/>
      </geometry>
    </visual>
    <inertial>
      <origin xyz="0 0 0"/>
      <mass value="0.07"/>
      <inertia ixx="0.000041907" ixy="0" ixz="0"
              iyy="0.000075157" iyz="0"
              izz="0.000107917"/>
    </inertial>
  </link>
  <link name="Right_Hand_link">
    <collision name="Right_Hand_collision">
      <origin rpy="0.00000 -1.57080 0.00000" xyz="0.00000 -0.04250 0.00000"/>
      <geometry>
        <box size="0.04000 0.08500 0.03500"/>
      </geometry>
    </collision>
    <visual name="Right_Hand">
      <origin rpy="0.00000 -1.57080 0.00000" xyz="0.00000 -0.04250 0.00000"/>
      <material name="Material"/>
      <geometry>
        <box size="0.04000 0.08500 0.03500"/>
      </geometry>
    </visual>
    <inertial>
      <origin xyz="0 0 0"/>
      <mass value="0.02"/>
      <inertia ixx="0.000014083" ixy="0" ixz="0"
              iyy="0.000004708" iyz="0"
              izz="0.000014708"/>
    </inertial>
  </link>
  <link name="Right_Lateral_Thigh_link">
    <collision name="Right_Lateral_Thigh_collision">
      <origin rpy="0.00000 -1.57080 0.00000" xyz="0.0225000 0.00000 0.00000"/>
      <geometry>
        <box size="0.04000 0.04000 0.04500"/>
      </geometry>
    </collision>
    <visual name="Right_Lateral_Thigh">
      <origin rpy="0.00000 -1.57080 0.00000" xyz="0.0225000 0.00000 0.00000"/>
      <material name="Material.002"/>
      <geometry>
        <box size="0.04000 0.04000 0.04500"/>
      </geometry>
    </visual>
    <inertial>
      <origin xyz="0 0 0"/>
      <mass value="0.07"/>
      <inertia ixx="0.00002114583" ixy="0" ixz="0"
              iyy="0.00002114583" iyz="0"
              izz="0.000018667"/>
    </inertial>
  </link>
  <link name="Right_Leg_link">
    <collision name="Right_Leg_collision">
      <origin rpy="-1.57080 0.00000 0.00000" xyz="0.00000 -0.03000 0.00000"/>
      <geometry>
        <box size="0.03500 0.05000 0.06000"/>
      </geometry>
    </collision>
    <visual name="Right_Leg">
      <origin rpy="-1.57080 0.00000 0.00000" xyz="0.00000 -0.03000 0.00000"/>
      <material name="Material.002"/>
      <geometry>
        <box size="0.03500 0.05000 0.06000"/>
      </geometry>
    </visual>
    <inertial>
      <origin xyz="0 0 0"/>
      <mass value="0.11"/>
      <inertia ixx="0.000055917" ixy="0" ixz="0"
              iyy="0.000044229" iyz="0"
              izz="0.000034146"/>
    </inertial>
  </link>
  <link name="Right_Shoulder_link">
    <collision name="Right_Shoulder_collision">
      <origin rpy="-1.57080 0.00000 0.00000" xyz="0.00000 0.00000 0.01000"/>
      <geometry>
        <box size="0.04000 0.02000 0.04000"/>
      </geometry>
    </collision>
    <visual name="Right_Shoulder">
      <origin rpy="-1.57080 0.00000 0.00000" xyz="0.00000 0.00000 0.01000"/>
      <material name="Material.002"/>
      <geometry>
        <box size="0.04000 0.02000 0.04000"/>
      </geometry>
    </visual>
    <inertial>
      <origin xyz="0 0 0"/>
      <mass value="0.06"/>
      <inertia ixx="0.00001" ixy="0" ixz="0"
              iyy="0.000016" iyz="0"
              izz="0.00001"/>
    </inertial>
  </link>
  <link name="Right_Thigh_link">
    <collision name="Right_Thigh_collision">
      <origin rpy="-1.57080 0.00000 0.00000" xyz="0.00000 -0.0250 0.00000"/>
      <geometry>
        <box size="0.03500 0.04000 0.0500"/>
      </geometry>
    </collision>
    <visual name="Right_Thigh">
      <origin rpy="-1.57080 0.00000 0.00000" xyz="0.00000 -0.0250 0.00000"/>
      <material name="Material.001"/>
      <geometry>
        <box size="0.03500 0.04000 0.0500"/>
      </geometry>
    </visual>
    <inertial>
      <origin xyz="0 0 0"/>
      <mass value="0.115"/>
      <inertia ixx="0.00003929166" ixy="0" ixz="0"
              iyy="0.00003569791" iyz="0"
              izz="0.000027073"/>
    </inertial>
  </link>
  <material name="Material">
    <color rgba="0.60784 0.80000 0.72941 1.00000"/>
  </material>
  <material name="Material.001">
    <color rgba="0.07059 0.50980 0.80000 1.00000"/>
  </material>
  <material name="Material.002">
    <color rgba="0.10196 0.08235 0.11765 1.00000"/>
  </material>
</robot>